[2021-06-07 01:13:57,928] {taskinstance.py:876} INFO - Dependencies all met for <TaskInstance: stage_data_redshift.load_product_from_s3_to_redshift 2021-06-07T01:13:48.422975+00:00 [queued]>
[2021-06-07 01:13:57,940] {taskinstance.py:876} INFO - Dependencies all met for <TaskInstance: stage_data_redshift.load_product_from_s3_to_redshift 2021-06-07T01:13:48.422975+00:00 [queued]>
[2021-06-07 01:13:57,940] {taskinstance.py:1067} INFO - 
--------------------------------------------------------------------------------
[2021-06-07 01:13:57,940] {taskinstance.py:1068} INFO - Starting attempt 1 of 1
[2021-06-07 01:13:57,942] {taskinstance.py:1069} INFO - 
--------------------------------------------------------------------------------
[2021-06-07 01:13:57,948] {taskinstance.py:1087} INFO - Executing <Task(PythonOperator): load_product_from_s3_to_redshift> on 2021-06-07T01:13:48.422975+00:00
[2021-06-07 01:13:57,953] {standard_task_runner.py:52} INFO - Started process 292 to run task
[2021-06-07 01:13:57,955] {standard_task_runner.py:76} INFO - Running: ['***', 'tasks', 'run', 'stage_data_redshift', 'load_product_from_s3_to_redshift', '2021-06-07T01:13:48.422975+00:00', '--job-id', '61', '--pool', 'default_pool', '--raw', '--subdir', 'DAGS_FOLDER/load_data_to_redshift.py', '--cfg-path', '/tmp/tmpeb9b0k4z', '--error-file', '/tmp/tmpk3rnug12']
[2021-06-07 01:13:57,956] {standard_task_runner.py:77} INFO - Job 61: Subtask load_product_from_s3_to_redshift
[2021-06-07 01:13:57,985] {logging_mixin.py:104} INFO - Running <TaskInstance: stage_data_redshift.load_product_from_s3_to_redshift 2021-06-07T01:13:48.422975+00:00 [running]> on host 21bd802337aa
[2021-06-07 01:13:58,026] {taskinstance.py:1282} INFO - Exporting the following env vars:
AIRFLOW_CTX_DAG_OWNER=***
AIRFLOW_CTX_DAG_ID=stage_data_redshift
AIRFLOW_CTX_TASK_ID=load_product_from_s3_to_redshift
AIRFLOW_CTX_EXECUTION_DATE=2021-06-07T01:13:48.422975+00:00
AIRFLOW_CTX_DAG_RUN_ID=manual__2021-06-07T01:13:48.422975+00:00
[2021-06-07 01:13:58,033] {connection.py:360} ERROR - Failed parsing the json for conn_id redshift
Traceback (most recent call last):
  File "/home/airflow/.local/lib/python3.6/site-packages/airflow/models/connection.py", line 357, in extra_dejson
    obj = json.loads(self.extra)
  File "/usr/local/lib/python3.6/json/__init__.py", line 354, in loads
    return _default_decoder.decode(s)
  File "/usr/local/lib/python3.6/json/decoder.py", line 339, in decode
    obj, end = self.raw_decode(s, idx=_w(s, 0).end())
  File "/usr/local/lib/python3.6/json/decoder.py", line 357, in raw_decode
    raise JSONDecodeError("Expecting value", s, err.value) from None
json.decoder.JSONDecodeError: Expecting value: line 1 column 1 (char 0)
[2021-06-07 01:13:58,033] {base.py:78} INFO - Using connection to: id: redshift. Host: doxcluster.craeubgpe2r5.us-east-1.redshift.amazonaws.com, Port: 5439, Schema: dox, Login: doxuser, Password: ***, extra: {}
[2021-06-07 01:13:58,033] {connection.py:360} ERROR - Failed parsing the json for conn_id redshift
Traceback (most recent call last):
  File "/home/airflow/.local/lib/python3.6/site-packages/airflow/models/connection.py", line 357, in extra_dejson
    obj = json.loads(self.extra)
  File "/usr/local/lib/python3.6/json/__init__.py", line 354, in loads
    return _default_decoder.decode(s)
  File "/usr/local/lib/python3.6/json/decoder.py", line 339, in decode
    obj, end = self.raw_decode(s, idx=_w(s, 0).end())
  File "/usr/local/lib/python3.6/json/decoder.py", line 357, in raw_decode
    raise JSONDecodeError("Expecting value", s, err.value) from None
json.decoder.JSONDecodeError: Expecting value: line 1 column 1 (char 0)
[2021-06-07 01:13:58,034] {connection.py:360} ERROR - Failed parsing the json for conn_id redshift
Traceback (most recent call last):
  File "/home/airflow/.local/lib/python3.6/site-packages/airflow/models/connection.py", line 357, in extra_dejson
    obj = json.loads(self.extra)
  File "/usr/local/lib/python3.6/json/__init__.py", line 354, in loads
    return _default_decoder.decode(s)
  File "/usr/local/lib/python3.6/json/decoder.py", line 339, in decode
    obj, end = self.raw_decode(s, idx=_w(s, 0).end())
  File "/usr/local/lib/python3.6/json/decoder.py", line 357, in raw_decode
    raise JSONDecodeError("Expecting value", s, err.value) from None
json.decoder.JSONDecodeError: Expecting value: line 1 column 1 (char 0)
[2021-06-07 01:13:58,034] {connection.py:360} ERROR - Failed parsing the json for conn_id redshift
Traceback (most recent call last):
  File "/home/airflow/.local/lib/python3.6/site-packages/airflow/models/connection.py", line 357, in extra_dejson
    obj = json.loads(self.extra)
  File "/usr/local/lib/python3.6/json/__init__.py", line 354, in loads
    return _default_decoder.decode(s)
  File "/usr/local/lib/python3.6/json/decoder.py", line 339, in decode
    obj, end = self.raw_decode(s, idx=_w(s, 0).end())
  File "/usr/local/lib/python3.6/json/decoder.py", line 357, in raw_decode
    raise JSONDecodeError("Expecting value", s, err.value) from None
json.decoder.JSONDecodeError: Expecting value: line 1 column 1 (char 0)
[2021-06-07 01:14:00,216] {dbapi.py:204} INFO - Running statement: 
COPY Product
FROM 's3://roxproject/data/Production.Product.csv'
IAM_ROLE 'arn:aws:iam::029258854698:role/doxRole'
IGNOREHEADER 1
DELIMITER ';', parameters: None
[2021-06-07 01:14:01,570] {python.py:151} INFO - Done. Returned value was: None
[2021-06-07 01:14:01,585] {taskinstance.py:1191} INFO - Marking task as SUCCESS. dag_id=stage_data_redshift, task_id=load_product_from_s3_to_redshift, execution_date=20210607T011348, start_date=20210607T011357, end_date=20210607T011401
[2021-06-07 01:14:01,624] {taskinstance.py:1245} INFO - 1 downstream tasks scheduled from follow-on schedule check
[2021-06-07 01:14:01,661] {local_task_job.py:151} INFO - Task exited with return code 0
