[2021-06-06 14:23:29,467] {taskinstance.py:876} INFO - Dependencies all met for <TaskInstance: lesson1.excercise5.list_keys 2021-06-06T14:23:28.192769+00:00 [queued]>
[2021-06-06 14:23:29,480] {taskinstance.py:876} INFO - Dependencies all met for <TaskInstance: lesson1.excercise5.list_keys 2021-06-06T14:23:28.192769+00:00 [queued]>
[2021-06-06 14:23:29,480] {taskinstance.py:1067} INFO - 
--------------------------------------------------------------------------------
[2021-06-06 14:23:29,480] {taskinstance.py:1068} INFO - Starting attempt 1 of 1
[2021-06-06 14:23:29,482] {taskinstance.py:1069} INFO - 
--------------------------------------------------------------------------------
[2021-06-06 14:23:29,490] {taskinstance.py:1087} INFO - Executing <Task(PythonOperator): list_keys> on 2021-06-06T14:23:28.192769+00:00
[2021-06-06 14:23:29,495] {standard_task_runner.py:52} INFO - Started process 601 to run task
[2021-06-06 14:23:29,498] {standard_task_runner.py:76} INFO - Running: ['***', 'tasks', 'run', 'lesson1.excercise5', 'list_keys', '2021-06-06T14:23:28.192769+00:00', '--job-id', '4', '--pool', 'default_pool', '--raw', '--subdir', 'DAGS_FOLDER/connection_hooks.py', '--cfg-path', '/tmp/tmprms1sjug', '--error-file', '/tmp/tmpvy6e0zl1']
[2021-06-06 14:23:29,498] {standard_task_runner.py:77} INFO - Job 4: Subtask list_keys
[2021-06-06 14:23:29,533] {logging_mixin.py:104} INFO - Running <TaskInstance: lesson1.excercise5.list_keys 2021-06-06T14:23:28.192769+00:00 [running]> on host 21bd802337aa
[2021-06-06 14:23:29,580] {taskinstance.py:1282} INFO - Exporting the following env vars:
AIRFLOW_CTX_DAG_OWNER=***
AIRFLOW_CTX_DAG_ID=lesson1.excercise5
AIRFLOW_CTX_TASK_ID=list_keys
AIRFLOW_CTX_EXECUTION_DATE=2021-06-06T14:23:28.192769+00:00
AIRFLOW_CTX_DAG_RUN_ID=manual__2021-06-06T14:23:28.192769+00:00
[2021-06-06 14:23:29,594] {connection_hooks.py:14} INFO - Listing Keys from roxproject/csv
[2021-06-06 14:23:29,594] {base_aws.py:368} INFO - Airflow Connection: aws_conn_id=aws_credentials
[2021-06-06 14:23:29,601] {base_aws.py:391} WARNING - Unable to use Airflow Connection for credentials.
[2021-06-06 14:23:29,602] {base_aws.py:392} INFO - Fallback on boto3 credential strategy
[2021-06-06 14:23:29,602] {base_aws.py:397} INFO - Creating session using boto3 credential strategy region_name=None
[2021-06-06 14:23:31,701] {taskinstance.py:1481} ERROR - Task failed with exception
Traceback (most recent call last):
  File "/home/airflow/.local/lib/python3.6/site-packages/airflow/models/taskinstance.py", line 1137, in _run_raw_task
    self._prepare_and_execute_task_with_callbacks(context, task)
  File "/home/airflow/.local/lib/python3.6/site-packages/airflow/models/taskinstance.py", line 1311, in _prepare_and_execute_task_with_callbacks
    result = self._execute_task(context, task_copy)
  File "/home/airflow/.local/lib/python3.6/site-packages/airflow/models/taskinstance.py", line 1341, in _execute_task
    result = task_copy.execute(context=context)
  File "/home/airflow/.local/lib/python3.6/site-packages/airflow/operators/python.py", line 150, in execute
    return_value = self.execute_callable()
  File "/home/airflow/.local/lib/python3.6/site-packages/airflow/operators/python.py", line 161, in execute_callable
    return self.python_callable(*self.op_args, **self.op_kwargs)
  File "/opt/airflow/dags/connection_hooks.py", line 15, in list_keys
    keys = hook.list_keys(bucket, prefix)
  File "/home/airflow/.local/lib/python3.6/site-packages/airflow/providers/amazon/aws/hooks/s3.py", line 62, in wrapper
    return func(*bound_args.args, **bound_args.kwargs)
  File "/home/airflow/.local/lib/python3.6/site-packages/airflow/providers/amazon/aws/hooks/s3.py", line 302, in list_keys
    for page in response:
  File "/home/airflow/.local/lib/python3.6/site-packages/botocore/paginate.py", line 255, in __iter__
    response = self._make_request(current_kwargs)
  File "/home/airflow/.local/lib/python3.6/site-packages/botocore/paginate.py", line 332, in _make_request
    return self._method(**current_kwargs)
  File "/home/airflow/.local/lib/python3.6/site-packages/botocore/client.py", line 357, in _api_call
    return self._make_api_call(operation_name, kwargs)
  File "/home/airflow/.local/lib/python3.6/site-packages/botocore/client.py", line 663, in _make_api_call
    operation_model, request_dict, request_context)
  File "/home/airflow/.local/lib/python3.6/site-packages/botocore/client.py", line 682, in _make_request
    return self._endpoint.make_request(operation_model, request_dict)
  File "/home/airflow/.local/lib/python3.6/site-packages/botocore/endpoint.py", line 102, in make_request
    return self._send_request(request_dict, operation_model)
  File "/home/airflow/.local/lib/python3.6/site-packages/botocore/endpoint.py", line 132, in _send_request
    request = self.create_request(request_dict, operation_model)
  File "/home/airflow/.local/lib/python3.6/site-packages/botocore/endpoint.py", line 116, in create_request
    operation_name=operation_model.name)
  File "/home/airflow/.local/lib/python3.6/site-packages/botocore/hooks.py", line 356, in emit
    return self._emitter.emit(aliased_event_name, **kwargs)
  File "/home/airflow/.local/lib/python3.6/site-packages/botocore/hooks.py", line 228, in emit
    return self._emit(event_name, kwargs)
  File "/home/airflow/.local/lib/python3.6/site-packages/botocore/hooks.py", line 211, in _emit
    response = handler(**kwargs)
  File "/home/airflow/.local/lib/python3.6/site-packages/botocore/signers.py", line 90, in handler
    return self.sign(operation_name, request)
  File "/home/airflow/.local/lib/python3.6/site-packages/botocore/signers.py", line 162, in sign
    auth.add_auth(request)
  File "/home/airflow/.local/lib/python3.6/site-packages/botocore/auth.py", line 373, in add_auth
    raise NoCredentialsError()
botocore.exceptions.NoCredentialsError: Unable to locate credentials
[2021-06-06 14:23:31,703] {taskinstance.py:1531} INFO - Marking task as FAILED. dag_id=lesson1.excercise5, task_id=list_keys, execution_date=20210606T142328, start_date=20210606T142329, end_date=20210606T142331
[2021-06-06 14:23:31,758] {local_task_job.py:151} INFO - Task exited with return code 1
