[2021-06-06 16:12:11,314] {taskinstance.py:876} INFO - Dependencies all met for <TaskInstance: create_rox_tables.drop_person_table 2021-06-06T16:12:09.973491+00:00 [queued]>
[2021-06-06 16:12:11,326] {taskinstance.py:876} INFO - Dependencies all met for <TaskInstance: create_rox_tables.drop_person_table 2021-06-06T16:12:09.973491+00:00 [queued]>
[2021-06-06 16:12:11,327] {taskinstance.py:1067} INFO - 
--------------------------------------------------------------------------------
[2021-06-06 16:12:11,327] {taskinstance.py:1068} INFO - Starting attempt 1 of 1
[2021-06-06 16:12:11,329] {taskinstance.py:1069} INFO - 
--------------------------------------------------------------------------------
[2021-06-06 16:12:11,337] {taskinstance.py:1087} INFO - Executing <Task(PostgresOperator): drop_person_table> on 2021-06-06T16:12:09.973491+00:00
[2021-06-06 16:12:11,344] {standard_task_runner.py:52} INFO - Started process 2664 to run task
[2021-06-06 16:12:11,346] {standard_task_runner.py:76} INFO - Running: ['***', 'tasks', 'run', 'create_rox_tables', 'drop_person_table', '2021-06-06T16:12:09.973491+00:00', '--job-id', '16', '--pool', 'default_pool', '--raw', '--subdir', 'DAGS_FOLDER/create_rox_tables.py', '--cfg-path', '/tmp/tmpitcfd3dm', '--error-file', '/tmp/tmpq3gvm3lb']
[2021-06-06 16:12:11,347] {standard_task_runner.py:77} INFO - Job 16: Subtask drop_person_table
[2021-06-06 16:12:11,374] {logging_mixin.py:104} INFO - Running <TaskInstance: create_rox_tables.drop_person_table 2021-06-06T16:12:09.973491+00:00 [running]> on host 21bd802337aa
[2021-06-06 16:12:11,411] {taskinstance.py:1282} INFO - Exporting the following env vars:
AIRFLOW_CTX_DAG_OWNER=***
AIRFLOW_CTX_DAG_ID=create_rox_tables
AIRFLOW_CTX_TASK_ID=drop_person_table
AIRFLOW_CTX_EXECUTION_DATE=2021-06-06T16:12:09.973491+00:00
AIRFLOW_CTX_DAG_RUN_ID=manual__2021-06-06T16:12:09.973491+00:00
[2021-06-06 16:12:11,411] {postgres.py:70} INFO - Executing: DROP TABLE IF EXISTS Person;
[2021-06-06 16:12:11,419] {base.py:78} INFO - Using connection to: id: redshift. Host: doxcluster.craeubgpe2r5.us-east-1.redshift.amazonaws.com, Port: 5439, Schema: dox, Login: doxuser, Password: ***, extra: {}
[2021-06-06 16:14:22,520] {taskinstance.py:1481} ERROR - Task failed with exception
Traceback (most recent call last):
  File "/home/airflow/.local/lib/python3.6/site-packages/airflow/models/taskinstance.py", line 1137, in _run_raw_task
    self._prepare_and_execute_task_with_callbacks(context, task)
  File "/home/airflow/.local/lib/python3.6/site-packages/airflow/models/taskinstance.py", line 1311, in _prepare_and_execute_task_with_callbacks
    result = self._execute_task(context, task_copy)
  File "/home/airflow/.local/lib/python3.6/site-packages/airflow/models/taskinstance.py", line 1341, in _execute_task
    result = task_copy.execute(context=context)
  File "/home/airflow/.local/lib/python3.6/site-packages/airflow/providers/postgres/operators/postgres.py", line 72, in execute
    self.hook.run(self.sql, self.autocommit, parameters=self.parameters)
  File "/home/airflow/.local/lib/python3.6/site-packages/airflow/hooks/dbapi.py", line 177, in run
    with closing(self.get_conn()) as conn:
  File "/home/airflow/.local/lib/python3.6/site-packages/airflow/providers/postgres/hooks/postgres.py", line 113, in get_conn
    self.conn = psycopg2.connect(**conn_args)
  File "/home/airflow/.local/lib/python3.6/site-packages/psycopg2/__init__.py", line 127, in connect
    conn = _connect(dsn, connection_factory=connection_factory, **kwasync)
psycopg2.OperationalError: could not connect to server: Connection timed out
	Is the server running on host "doxcluster.craeubgpe2r5.us-east-1.redshift.amazonaws.com" (54.152.52.67) and accepting
	TCP/IP connections on port 5439?

[2021-06-06 16:14:22,521] {taskinstance.py:1531} INFO - Marking task as FAILED. dag_id=create_rox_tables, task_id=drop_person_table, execution_date=20210606T161209, start_date=20210606T161211, end_date=20210606T161422
[2021-06-06 16:14:22,552] {local_task_job.py:151} INFO - Task exited with return code 1
