[2021-06-06 14:19:10,570] {taskinstance.py:876} INFO - Dependencies all met for <TaskInstance: lesson1.excercise5.list_keys 2021-06-06T14:19:08.802658+00:00 [queued]>
[2021-06-06 14:19:10,582] {taskinstance.py:876} INFO - Dependencies all met for <TaskInstance: lesson1.excercise5.list_keys 2021-06-06T14:19:08.802658+00:00 [queued]>
[2021-06-06 14:19:10,582] {taskinstance.py:1067} INFO - 
--------------------------------------------------------------------------------
[2021-06-06 14:19:10,582] {taskinstance.py:1068} INFO - Starting attempt 1 of 1
[2021-06-06 14:19:10,584] {taskinstance.py:1069} INFO - 
--------------------------------------------------------------------------------
[2021-06-06 14:19:10,590] {taskinstance.py:1087} INFO - Executing <Task(PythonOperator): list_keys> on 2021-06-06T14:19:08.802658+00:00
[2021-06-06 14:19:10,595] {standard_task_runner.py:52} INFO - Started process 221 to run task
[2021-06-06 14:19:10,597] {standard_task_runner.py:76} INFO - Running: ['***', 'tasks', 'run', 'lesson1.excercise5', 'list_keys', '2021-06-06T14:19:08.802658+00:00', '--job-id', '3', '--pool', 'default_pool', '--raw', '--subdir', 'DAGS_FOLDER/connection_hooks.py', '--cfg-path', '/tmp/tmpry495dop', '--error-file', '/tmp/tmp9fa32tdu']
[2021-06-06 14:19:10,597] {standard_task_runner.py:77} INFO - Job 3: Subtask list_keys
[2021-06-06 14:19:10,624] {logging_mixin.py:104} INFO - Running <TaskInstance: lesson1.excercise5.list_keys 2021-06-06T14:19:08.802658+00:00 [running]> on host 21bd802337aa
[2021-06-06 14:19:10,659] {taskinstance.py:1282} INFO - Exporting the following env vars:
AIRFLOW_CTX_DAG_OWNER=***
AIRFLOW_CTX_DAG_ID=lesson1.excercise5
AIRFLOW_CTX_TASK_ID=list_keys
AIRFLOW_CTX_EXECUTION_DATE=2021-06-06T14:19:08.802658+00:00
AIRFLOW_CTX_DAG_RUN_ID=manual__2021-06-06T14:19:08.802658+00:00
[2021-06-06 14:19:10,664] {taskinstance.py:1481} ERROR - Task failed with exception
Traceback (most recent call last):
  File "/home/airflow/.local/lib/python3.6/site-packages/airflow/models/taskinstance.py", line 1137, in _run_raw_task
    self._prepare_and_execute_task_with_callbacks(context, task)
  File "/home/airflow/.local/lib/python3.6/site-packages/airflow/models/taskinstance.py", line 1311, in _prepare_and_execute_task_with_callbacks
    result = self._execute_task(context, task_copy)
  File "/home/airflow/.local/lib/python3.6/site-packages/airflow/models/taskinstance.py", line 1341, in _execute_task
    result = task_copy.execute(context=context)
  File "/home/airflow/.local/lib/python3.6/site-packages/airflow/operators/python.py", line 150, in execute
    return_value = self.execute_callable()
  File "/home/airflow/.local/lib/python3.6/site-packages/airflow/operators/python.py", line 161, in execute_callable
    return self.python_callable(*self.op_args, **self.op_kwargs)
  File "/opt/airflow/dags/connection_hooks.py", line 12, in list_keys
    bucket = Variable.get('s3_bucket')
  File "/home/airflow/.local/lib/python3.6/site-packages/airflow/models/variable.py", line 140, in get
    raise KeyError(f'Variable {key} does not exist')
KeyError: 'Variable s3_bucket does not exist'
[2021-06-06 14:19:10,666] {taskinstance.py:1531} INFO - Marking task as FAILED. dag_id=lesson1.excercise5, task_id=list_keys, execution_date=20210606T141908, start_date=20210606T141910, end_date=20210606T141910
[2021-06-06 14:19:10,688] {local_task_job.py:151} INFO - Task exited with return code 1
